test_get_selected_satellite_name (__main__.TestAlgorithmCore) ... ok
test_select_satellite_with_max_connections (__main__.TestAlgorithmCore) ... ok
test_select_satellite_with_previous_selection_count (__main__.TestAlgorithmCore) ... ok
test_set_get_adjacency_matrices (__main__.TestAlgorithmCore) ... ok
test_set_get_satellite_names (__main__.TestAlgorithmCore) ... ok
test_start_algorithm_steps (__main__.TestAlgorithmCore) ... ERROR
test_start_algorithm_steps_one_satellite (__main__.TestAlgorithmCore) ... ERROR
test_auto_generate_satellite_names (__main__.TestAlgorithmHandler) ... ok
test_parse_data (__main__.TestAlgorithmHandler) ... ERROR
test_parse_file (__main__.TestAlgorithmHandler) ... ok
test_read_adjacency_matrices_invalid_file (__main__.TestAlgorithmHandler) ... ok
test_validate_adjacency_matrices (__main__.TestAlgorithmHandler) ... ok
test_validate_adjacency_matrices_not_square (__main__.TestAlgorithmHandler) ... ok
test_validate_adjacency_matrices_not_symmetry (__main__.TestAlgorithmHandler) ... ok
test_process_algorithm_output (__main__.TestAlgorithmOutput) ... ok
test_set_and_get_result (__main__.TestAlgorithmOutput) ... ok
test_write_to_file (__main__.TestAlgorithmOutput) ... ERROR

======================================================================
ERROR: test_start_algorithm_steps (__main__.TestAlgorithmCore)
----------------------------------------------------------------------
Traceback (most recent call last):
  File "/Users/ash/Desktop/SPACE_FLTeam/unit_test_algorithm_component.py", line 85, in test_start_algorithm_steps
    self.algorithm.start_algorithm_steps()
  File "/Users/ash/Desktop/SPACE_FLTeam/flomps_algorithm/algorithm_core.py", line 201, in start_algorithm_steps
    self.output.write_to_file(algorithm_output)  # write to file.
  File "/Users/ash/Desktop/SPACE_FLTeam/flomps_algorithm/algorithm_output.py", line 90, in write_to_file
    self._write_original_format(algorithm_output)
  File "/Users/ash/Desktop/SPACE_FLTeam/flomps_algorithm/algorithm_output.py", line 106, in _write_original_format
    with open(output_file, 'w') as file:
FileNotFoundError: [Errno 2] No such file or directory: '/Users/ash/Desktop/SPACE_FLTeam/flomps_algorithm/output/flam_20250603_135805.txt'

======================================================================
ERROR: test_start_algorithm_steps_one_satellite (__main__.TestAlgorithmCore)
----------------------------------------------------------------------
Traceback (most recent call last):
  File "/Users/ash/Desktop/SPACE_FLTeam/unit_test_algorithm_component.py", line 99, in test_start_algorithm_steps_one_satellite
    self.algorithm.start_algorithm_steps()
  File "/Users/ash/Desktop/SPACE_FLTeam/flomps_algorithm/algorithm_core.py", line 201, in start_algorithm_steps
    self.output.write_to_file(algorithm_output)  # write to file.
  File "/Users/ash/Desktop/SPACE_FLTeam/flomps_algorithm/algorithm_output.py", line 90, in write_to_file
    self._write_original_format(algorithm_output)
  File "/Users/ash/Desktop/SPACE_FLTeam/flomps_algorithm/algorithm_output.py", line 106, in _write_original_format
    with open(output_file, 'w') as file:
FileNotFoundError: [Errno 2] No such file or directory: '/Users/ash/Desktop/SPACE_FLTeam/flomps_algorithm/output/flam_20250603_135805.txt'

======================================================================
ERROR: test_parse_data (__main__.TestAlgorithmHandler)
----------------------------------------------------------------------
Traceback (most recent call last):
  File "/Users/ash/Desktop/SPACE_FLTeam/unit_test_algorithm_component.py", line 160, in test_parse_data
    self.handler.parse_data(matrices)
  File "/Users/ash/Desktop/SPACE_FLTeam/flomps_algorithm/algorithm_handler.py", line 137, in parse_data
    self.adjacency_matrices = data.matrices
AttributeError: 'list' object has no attribute 'matrices'

======================================================================
ERROR: test_write_to_file (__main__.TestAlgorithmOutput)
----------------------------------------------------------------------
Traceback (most recent call last):
  File "/Users/ash/Desktop/SPACE_FLTeam/unit_test_algorithm_component.py", line 200, in test_write_to_file
    self.output.write_to_file(self.algorithm_output)
  File "/Users/ash/Desktop/SPACE_FLTeam/flomps_algorithm/algorithm_output.py", line 90, in write_to_file
    self._write_original_format(algorithm_output)
  File "/Users/ash/Desktop/SPACE_FLTeam/flomps_algorithm/algorithm_output.py", line 106, in _write_original_format
    with open(output_file, 'w') as file:
FileNotFoundError: [Errno 2] No such file or directory: '/Users/ash/Desktop/SPACE_FLTeam/flomps_algorithm/output/flam_20250603_135805.txt'

----------------------------------------------------------------------
Ran 17 tests in 0.008s

FAILED (errors=4)
